Workbook

Sheet 31 Maret 2026
H1: Helper Kategori | I1: Helper Pilihan Bahan
A2: SATUAN PELAYANAN PEMENUHAN GIZI (SPPG) BATTU WINANGUN NOTA PEMESANAN BAHAN MAKANAN | H2: =IFERROR('Master Data'!E2,"") -> Karbohidrat
H3: =IFERROR('Master Data'!E3,"") -> Protein Hewani
H4: =IFERROR('Master Data'!E4,"") -> Protein Nabati
H5: =IFERROR('Master Data'!E5,"") -> Sayur
H6: =IFERROR('Master Data'!E6,"") -> Buah
A7: Tanggal | B7: Kategori Makanan | C7: Bahan Makanan | D7: Satuan | E7: Jumlah | H7: =IFERROR('Master Data'!E7,"") -> Bumbu Masak Sayur
A8: 46112 | B8: Karbohidrat | C8: Beras | D8: =IF(C8="","",IFERROR(VLOOKUP(C8,'Master Data'!$B$2:$C$527,2,FALSE),"")) -> Kg | E8: 271 | H8: =IFERROR('Master Data'!E8,"") -> Bumbu Masak Sembako | I8: =IFERROR(__xludf.DUMMYFUNCTION("IFERROR(TRANSPOSE(FILTER('Master Data'!$B$2:$B$527,'Master Data'!$A$2:$A$527=$B8)),"""")"),"Beras") -> Beras | J8: =IFERROR(__xludf.DUMMYFUNCTION("""COMPUTED_VALUE"""),"Mie") -> Mie | K8: =IFERROR(__xludf.DUMMYFUNCTION("""COMPUTED_VALUE"""),"Kentang") -> Kentang | L8: =IFERROR(__xludf.DUMMYFUNCTION("""COMPUTED_VALUE"""),"Jagung") -> Jagung | M8: =IFERROR(__xludf.DUMMYFUNCTION("""COMPUTED_VALUE"""),"Roti") -> Roti | N8: =IFERROR(__xludf.DUMMYFUNCTION("""COMPUTED_VALUE"""),"Singkong") -> Singkong | O8: =IFERROR(__xludf.DUMMYFUNCTION("""COMPUTED_VALUE"""),"Ubi") -> Ubi | P8: =IFERROR(__xludf.DUMMYFUNCTION("""COMPUTED_VALUE"""),"Makaroni") -> Makaroni
A9: 46112 | B9: Protein Hewani | C9: Daging Ayam Fillet | D9: =IF(C9="","",IFERROR(VLOOKUP(C9,'Master Data'!$B$2:$C$527,2,FALSE),"")) -> Kg | E9: 148 | H9: =IFERROR('Master Data'!E9,"") -> Isi Ulang | I9: =IFERROR(__xludf.DUMMYFUNCTION("IFERROR(TRANSPOSE(FILTER('Master Data'!$B$2:$B$527,'Master Data'!$A$2:$A$527=$B9)),"""")"),"Daging Ayam Fillet") -> Daging Ayam Fillet | J9: =IFERROR(__xludf.DUMMYFUNCTION("""COMPUTED_VALUE"""),"Daging Ayam Tulang (Potong)") -> Daging Ayam Tulang (Potong) | K9: =IFERROR(__xludf.DUMMYFUNCTION("""COMPUTED_VALUE"""),"Ikan Patin Fillet") -> Ikan Patin Fillet | L9: =IFERROR(__xludf.DUMMYFUNCTION("""COMPUTED_VALUE"""),"Telur") -> Telur | M9: =IFERROR(__xludf.DUMMYFUNCTION("""COMPUTED_VALUE"""),"Ikan giling") -> Ikan giling | N9: =IFERROR(__xludf.DUMMYFUNCTION("""COMPUTED_VALUE"""),"Ayam Giling") -> Ayam Giling | O9: =IFERROR(__xludf.DUMMYFUNCTION("""COMPUTED_VALUE"""),"Daging Sapi") -> Daging Sapi | P9: =IFERROR(__xludf.DUMMYFUNCTION("""COMPUTED_VALUE"""),"Udang") -> Udang | Q9: =IFERROR(__xludf.DUMMYFUNCTION("""COMPUTED_VALUE"""),"Susu UHT") -> Susu UHT
A10: 46112 | B10: Protein Nabati | C10: Tahu | D10: =IF(C10="","",IFERROR(VLOOKUP(C10,'Master Data'!$B$2:$C$527,2,FALSE),"")) -> Pcs | E10: 3355 | H10: =IFERROR('Master Data'!E10,"") -> Packaging | I10: =IFERROR(__xludf.DUMMYFUNCTION("IFERROR(TRANSPOSE(FILTER('Master Data'!$B$2:$B$527,'Master Data'!$A$2:$A$527=$B10)),"""")"),"Tempe") -> Tempe | J10: =IFERROR(__xludf.DUMMYFUNCTION("""COMPUTED_VALUE"""),"Tahu") -> Tahu | K10: =IFERROR(__xludf.DUMMYFUNCTION("""COMPUTED_VALUE"""),"Kacang Hijau") -> Kacang Hijau | L10: =IFERROR(__xludf.DUMMYFUNCTION("""COMPUTED_VALUE"""),"Kacang Tanah") -> Kacang Tanah | M10: =IFERROR(__xludf.DUMMYFUNCTION("""COMPUTED_VALUE"""),"Kedelai") -> Kedelai | N10: =IFERROR(__xludf.DUMMYFUNCTION("""COMPUTED_VALUE"""),"Oncom") -> Oncom
A11: 46112 | B11: Sayur | C11: Labu Siam | D11: =IF(C11="","",IFERROR(VLOOKUP(C11,'Master Data'!$B$2:$C$527,2,FALSE),"")) -> Kg | E11: 235 | H11: =IFERROR('Master Data'!E12,"") | I11: =IFERROR(__xludf.DUMMYFUNCTION("IFERROR(TRANSPOSE(FILTER('Master Data'!$B$2:$B$527,'Master Data'!$A$2:$A$527=$B11)),"""")"),"Wortel") -> Wortel | J11: =IFERROR(__xludf.DUMMYFUNCTION("""COMPUTED_VALUE"""),"Kacang Panjang") -> Kacang Panjang | K11: =IFERROR(__xludf.DUMMYFUNCTION("""COMPUTED_VALUE"""),"Tauge") -> Tauge | L11: =IFERROR(__xludf.DUMMYFUNCTION("""COMPUTED_VALUE"""),"Kubis") -> Kubis | M11: =IFERROR(__xludf.DUMMYFUNCTION("""COMPUTED_VALUE"""),"Buncis") -> Buncis | N11: =IFERROR(__xludf.DUMMYFUNCTION("""COMPUTED_VALUE"""),"Kembang Kol") -> Kembang Kol | O11: =IFERROR(__xludf.DUMMYFUNCTION("""COMPUTED_VALUE"""),"Sawi Putih") -> Sawi Putih | P11: =IFERROR(__xludf.DUMMYFUNCTION("""COMPUTED_VALUE"""),"Caisin") -> Caisin | Q11: =IFERROR(__xludf.DUMMYFUNCTION("""COMPUTED_VALUE"""),"Timun") -> Timun | R11: =IFERROR(__xludf.DUMMYFUNCTION("""COMPUTED_VALUE"""),"Daun Bawang") -> Daun Bawang | S11: =IFERROR(__xludf.DUMMYFUNCTION("""COMPUTED_VALUE"""),"Labu Siam") -> Labu Siam | T11: =IFERROR(__xludf.DUMMYFUNCTION("""COMPUTED_VALUE"""),"Tomat") -> Tomat | U11: =IFERROR(__xludf.DUMMYFUNCTION("""COMPUTED_VALUE"""),"Kemangi") -> Kemangi | V11: =IFERROR(__xludf.DUMMYFUNCTION("""COMPUTED_VALUE"""),"Jagung ") -> Jagung
A12: 46112 | B12: Sayur | C12: Wortel | D12: =IF(C12="","",IFERROR(VLOOKUP(C12,'Master Data'!$B$2:$C$527,2,FALSE),"")) -> Kg | E12: 30 | H12: =IFERROR('Master Data'!E14,"") | I12: =IFERROR(__xludf.DUMMYFUNCTION("IFERROR(TRANSPOSE(FILTER('Master Data'!$B$2:$B$527,'Master Data'!$A$2:$A$527=$B12)),"""")"),"Wortel") -> Wortel | J12: =IFERROR(__xludf.DUMMYFUNCTION("""COMPUTED_VALUE"""),"Kacang Panjang") -> Kacang Panjang | K12: =IFERROR(__xludf.DUMMYFUNCTION("""COMPUTED_VALUE"""),"Tauge") -> Tauge | L12: =IFERROR(__xludf.DUMMYFUNCTION("""COMPUTED_VALUE"""),"Kubis") -> Kubis | M12: =IFERROR(__xludf.DUMMYFUNCTION("""COMPUTED_VALUE"""),"Buncis") -> Buncis | N12: =IFERROR(__xludf.DUMMYFUNCTION("""COMPUTED_VALUE"""),"Kembang Kol") -> Kembang Kol | O12: =IFERROR(__xludf.DUMMYFUNCTION("""COMPUTED_VALUE"""),"Sawi Putih") -> Sawi Putih | P12: =IFERROR(__xludf.DUMMYFUNCTION("""COMPUTED_VALUE"""),"Caisin") -> Caisin | Q12: =IFERROR(__xludf.DUMMYFUNCTION("""COMPUTED_VALUE"""),"Timun") -> Timun | R12: =IFERROR(__xludf.DUMMYFUNCTION("""COMPUTED_VALUE"""),"Daun Bawang") -> Daun Bawang | S12: =IFERROR(__xludf.DUMMYFUNCTION("""COMPUTED_VALUE"""),"Labu Siam") -> Labu Siam | T12: =IFERROR(__xludf.DUMMYFUNCTION("""COMPUTED_VALUE"""),"Tomat") -> Tomat | U12: =IFERROR(__xludf.DUMMYFUNCTION("""COMPUTED_VALUE"""),"Kemangi") -> Kemangi | V12: =IFERROR(__xludf.DUMMYFUNCTION("""COMPUTED_VALUE"""),"Jagung ") -> Jagung
A13: 46112 | B13: Bumbu Masak Sayur | C13: Cabe Merah | D13: =IF(C13="","",IFERROR(VLOOKUP(C13,'Master Data'!$B$2:$C$527,2,FALSE),"")) -> Kg | E13: 3 | H13: =IFERROR('Master Data'!E17,"") | I13: =IFERROR(__xludf.DUMMYFUNCTION("IFERROR(TRANSPOSE(FILTER('Master Data'!$B$2:$B$527,'Master Data'!$A$2:$A$527=$B13)),"""")"),"Bawang Merah") -> Bawang Merah | J13: =IFERROR(__xludf.DUMMYFUNCTION("""COMPUTED_VALUE"""),"Bawang Putih") -> Bawang Putih | K13: =IFERROR(__xludf.DUMMYFUNCTION("""COMPUTED_VALUE"""),"Laos") -> Laos | L13: =IFERROR(__xludf.DUMMYFUNCTION("""COMPUTED_VALUE"""),"Serai") -> Serai | M13: =IFERROR(__xludf.DUMMYFUNCTION("""COMPUTED_VALUE"""),"Cabe Merah") -> Cabe Merah | N13: =IFERROR(__xludf.DUMMYFUNCTION("""COMPUTED_VALUE"""),"Bawang Bombay") -> Bawang Bombay | O13: =IFERROR(__xludf.DUMMYFUNCTION("""COMPUTED_VALUE"""),"Ketumbar") -> Ketumbar | P13: =IFERROR(__xludf.DUMMYFUNCTION("""COMPUTED_VALUE"""),"Kencur") -> Kencur | Q13: =IFERROR(__xludf.DUMMYFUNCTION("""COMPUTED_VALUE"""),"Kunyit") -> Kunyit | R13: =IFERROR(__xludf.DUMMYFUNCTION("""COMPUTED_VALUE"""),"Jahe") -> Jahe | S13: =IFERROR(__xludf.DUMMYFUNCTION("""COMPUTED_VALUE"""),"Kelapa Parut") -> Kelapa Parut | T13: =IFERROR(__xludf.DUMMYFUNCTION("""COMPUTED_VALUE"""),"Cabe Ijo") -> Cabe Ijo
A14: 46112 | B14: Sayur | C14: Daun Bawang | D14: =IF(C14="","",IFERROR(VLOOKUP(C14,'Master Data'!$B$2:$C$527,2,FALSE),"")) -> Kg | E14: 3 | H14: =IFERROR('Master Data'!E18,"") | I14: =IFERROR(__xludf.DUMMYFUNCTION("IFERROR(TRANSPOSE(FILTER('Master Data'!$B$2:$B$527,'Master Data'!$A$2:$A$527=$B14)),"""")"),"Wortel") -> Wortel | J14: =IFERROR(__xludf.DUMMYFUNCTION("""COMPUTED_VALUE"""),"Kacang Panjang") -> Kacang Panjang | K14: =IFERROR(__xludf.DUMMYFUNCTION("""COMPUTED_VALUE"""),"Tauge") -> Tauge | L14: =IFERROR(__xludf.DUMMYFUNCTION("""COMPUTED_VALUE"""),"Kubis") -> Kubis | M14: =IFERROR(__xludf.DUMMYFUNCTION("""COMPUTED_VALUE"""),"Buncis") -> Buncis | N14: =IFERROR(__xludf.DUMMYFUNCTION("""COMPUTED_VALUE"""),"Kembang Kol") -> Kembang Kol | O14: =IFERROR(__xludf.DUMMYFUNCTION("""COMPUTED_VALUE"""),"Sawi Putih") -> Sawi Putih | P14: =IFERROR(__xludf.DUMMYFUNCTION("""COMPUTED_VALUE"""),"Caisin") -> Caisin | Q14: =IFERROR(__xludf.DUMMYFUNCTION("""COMPUTED_VALUE"""),"Timun") -> Timun | R14: =IFERROR(__xludf.DUMMYFUNCTION("""COMPUTED_VALUE"""),"Daun Bawang") -> Daun Bawang | S14: =IFERROR(__xludf.DUMMYFUNCTION("""COMPUTED_VALUE"""),"Labu Siam") -> Labu Siam | T14: =IFERROR(__xludf.DUMMYFUNCTION("""COMPUTED_VALUE"""),"Tomat") -> Tomat | U14: =IFERROR(__xludf.DUMMYFUNCTION("""COMPUTED_VALUE"""),"Kemangi") -> Kemangi | V14: =IFERROR(__xludf.DUMMYFUNCTION("""COMPUTED_VALUE"""),"Jagung ") -> Jagung
A15: 46112 | B15: Bumbu Masak Sayur | C15: Bawang Merah | D15: =IF(C15="","",IFERROR(VLOOKUP(C15,'Master Data'!$B$2:$C$527,2,FALSE),"")) -> Kg | E15: 4 | H15: =IFERROR('Master Data'!E19,"") | I15: =IFERROR(__xludf.DUMMYFUNCTION("IFERROR(TRANSPOSE(FILTER('Master Data'!$B$2:$B$527,'Master Data'!$A$2:$A$527=$B15)),"""")"),"Bawang Merah") -> Bawang Merah | J15: =IFERROR(__xludf.DUMMYFUNCTION("""COMPUTED_VALUE"""),"Bawang Putih") -> Bawang Putih | K15: =IFERROR(__xludf.DUMMYFUNCTION("""COMPUTED_VALUE"""),"Laos") -> Laos | L15: =IFERROR(__xludf.DUMMYFUNCTION("""COMPUTED_VALUE"""),"Serai") -> Serai | M15: =IFERROR(__xludf.DUMMYFUNCTION("""COMPUTED_VALUE"""),"Cabe Merah") -> Cabe Merah | N15: =IFERROR(__xludf.DUMMYFUNCTION("""COMPUTED_VALUE"""),"Bawang Bombay") -> Bawang Bombay | O15: =IFERROR(__xludf.DUMMYFUNCTION("""COMPUTED_VALUE"""),"Ketumbar") -> Ketumbar | P15: =IFERROR(__xludf.DUMMYFUNCTION("""COMPUTED_VALUE"""),"Kencur") -> Kencur | Q15: =IFERROR(__xludf.DUMMYFUNCTION("""COMPUTED_VALUE"""),"Kunyit") -> Kunyit | R15: =IFERROR(__xludf.DUMMYFUNCTION("""COMPUTED_VALUE"""),"Jahe") -> Jahe | S15: =IFERROR(__xludf.DUMMYFUNCTION("""COMPUTED_VALUE"""),"Kelapa Parut") -> Kelapa Parut | T15: =IFERROR(__xludf.DUMMYFUNCTION("""COMPUTED_VALUE"""),"Cabe Ijo") -> Cabe Ijo
A16: 46112 | B16: Bumbu Masak Sayur | C16: Bawang Putih | D16: =IF(C16="","",IFERROR(VLOOKUP(C16,'Master Data'!$B$2:$C$527,2,FALSE),"")) -> Kg | E16: 4 | H16: =IFERROR('Master Data'!E21,"") | I16: =IFERROR(__xludf.DUMMYFUNCTION("IFERROR(TRANSPOSE(FILTER('Master Data'!$B$2:$B$527,'Master Data'!$A$2:$A$527=$B16)),"""")"),"Bawang Merah") -> Bawang Merah | J16: =IFERROR(__xludf.DUMMYFUNCTION("""COMPUTED_VALUE"""),"Bawang Putih") -> Bawang Putih | K16: =IFERROR(__xludf.DUMMYFUNCTION("""COMPUTED_VALUE"""),"Laos") -> Laos | L16: =IFERROR(__xludf.DUMMYFUNCTION("""COMPUTED_VALUE"""),"Serai") -> Serai | M16: =IFERROR(__xludf.DUMMYFUNCTION("""COMPUTED_VALUE"""),"Cabe Merah") -> Cabe Merah | N16: =IFERROR(__xludf.DUMMYFUNCTION("""COMPUTED_VALUE"""),"Bawang Bombay") -> Bawang Bombay | O16: =IFERROR(__xludf.DUMMYFUNCTION("""COMPUTED_VALUE"""),"Ketumbar") -> Ketumbar | P16: =IFERROR(__xludf.DUMMYFUNCTION("""COMPUTED_VALUE"""),"Kencur") -> Kencur | Q16: =IFERROR(__xludf.DUMMYFUNCTION("""COMPUTED_VALUE"""),"Kunyit") -> Kunyit | R16: =IFERROR(__xludf.DUMMYFUNCTION("""COMPUTED_VALUE"""),"Jahe") -> Jahe | S16: =IFERROR(__xludf.DUMMYFUNCTION("""COMPUTED_VALUE"""),"Kelapa Parut") -> Kelapa Parut | T16: =IFERROR(__xludf.DUMMYFUNCTION("""COMPUTED_VALUE"""),"Cabe Ijo") -> Cabe Ijo
A17: 46112 | B17: Bumbu Masak Sayur | C17: Bawang Bombay | D17: =IF(C17="","",IFERROR(VLOOKUP(C17,'Master Data'!$B$2:$C$527,2,FALSE),"")) -> Kg | E17: 3 | H17: =IFERROR('Master Data'!E22,"") | I17: =IFERROR(__xludf.DUMMYFUNCTION("IFERROR(TRANSPOSE(FILTER('Master Data'!$B$2:$B$527,'Master Data'!$A$2:$A$527=$B17)),"""")"),"Bawang Merah") -> Bawang Merah | J17: =IFERROR(__xludf.DUMMYFUNCTION("""COMPUTED_VALUE"""),"Bawang Putih") -> Bawang Putih | K17: =IFERROR(__xludf.DUMMYFUNCTION("""COMPUTED_VALUE"""),"Laos") -> Laos | L17: =IFERROR(__xludf.DUMMYFUNCTION("""COMPUTED_VALUE"""),"Serai") -> Serai | M17: =IFERROR(__xludf.DUMMYFUNCTION("""COMPUTED_VALUE"""),"Cabe Merah") -> Cabe Merah | N17: =IFERROR(__xludf.DUMMYFUNCTION("""COMPUTED_VALUE"""),"Bawang Bombay") -> Bawang Bombay | O17: =IFERROR(__xludf.DUMMYFUNCTION("""COMPUTED_VALUE"""),"Ketumbar") -> Ketumbar | P17: =IFERROR(__xludf.DUMMYFUNCTION("""COMPUTED_VALUE"""),"Kencur") -> Kencur | Q17: =IFERROR(__xludf.DUMMYFUNCTION("""COMPUTED_VALUE"""),"Kunyit") -> Kunyit | R17: =IFERROR(__xludf.DUMMYFUNCTION("""COMPUTED_VALUE"""),"Jahe") -> Jahe | S17: =IFERROR(__xludf.DUMMYFUNCTION("""COMPUTED_VALUE"""),"Kelapa Parut") -> Kelapa Parut | T17: =IFERROR(__xludf.DUMMYFUNCTION("""COMPUTED_VALUE"""),"Cabe Ijo") -> Cabe Ijo
A18: 46112 | B18: Sayur | C18: Tomat | D18: =IF(C18="","",IFERROR(VLOOKUP(C18,'Master Data'!$B$2:$C$527,2,FALSE),"")) -> Kg | E18: 15 | H18: =IFERROR('Master Data'!E23,"") | I18: =IFERROR(__xludf.DUMMYFUNCTION("IFERROR(TRANSPOSE(FILTER('Master Data'!$B$2:$B$527,'Master Data'!$A$2:$A$527=$B18)),"""")"),"Wortel") -> Wortel | J18: =IFERROR(__xludf.DUMMYFUNCTION("""COMPUTED_VALUE"""),"Kacang Panjang") -> Kacang Panjang | K18: =IFERROR(__xludf.DUMMYFUNCTION("""COMPUTED_VALUE"""),"Tauge") -> Tauge | L18: =IFERROR(__xludf.DUMMYFUNCTION("""COMPUTED_VALUE"""),"Kubis") -> Kubis | M18: =IFERROR(__xludf.DUMMYFUNCTION("""COMPUTED_VALUE"""),"Buncis") -> Buncis | N18: =IFERROR(__xludf.DUMMYFUNCTION("""COMPUTED_VALUE"""),"Kembang Kol") -> Kembang Kol | O18: =IFERROR(__xludf.DUMMYFUNCTION("""COMPUTED_VALUE"""),"Sawi Putih") -> Sawi Putih | P18: =IFERROR(__xludf.DUMMYFUNCTION("""COMPUTED_VALUE"""),"Caisin") -> Caisin | Q18: =IFERROR(__xludf.DUMMYFUNCTION("""COMPUTED_VALUE"""),"Timun") -> Timun | R18: =IFERROR(__xludf.DUMMYFUNCTION("""COMPUTED_VALUE"""),"Daun Bawang") -> Daun Bawang | S18: =IFERROR(__xludf.DUMMYFUNCTION("""COMPUTED_VALUE"""),"Labu Siam") -> Labu Siam | T18: =IFERROR(__xludf.DUMMYFUNCTION("""COMPUTED_VALUE"""),"Tomat") -> Tomat | U18: =IFERROR(__xludf.DUMMYFUNCTION("""COMPUTED_VALUE"""),"Kemangi") -> Kemangi | V18: =IFERROR(__xludf.DUMMYFUNCTION("""COMPUTED_VALUE"""),"Jagung ") -> Jagung
A19: 46112 | B19: Buah | C19: Melon | D19: =IF(C19="","",IFERROR(VLOOKUP(C19,'Master Data'!$B$2:$C$527,2,FALSE),"")) -> Kg | E19: 598 | H19: =IFERROR('Master Data'!E25,"") | I19: =IFERROR(__xludf.DUMMYFUNCTION("IFERROR(TRANSPOSE(FILTER('Master Data'!$B$2:$B$527,'Master Data'!$A$2:$A$527=$B19)),"""")"),"Melon") -> Melon | J19: =IFERROR(__xludf.DUMMYFUNCTION("""COMPUTED_VALUE"""),"Semangka") -> Semangka | K19: =IFERROR(__xludf.DUMMYFUNCTION("""COMPUTED_VALUE"""),"Jeruk") -> Jeruk | L19: =IFERROR(__xludf.DUMMYFUNCTION("""COMPUTED_VALUE"""),"Pisang") -> Pisang | M19: =IFERROR(__xludf.DUMMYFUNCTION("""COMPUTED_VALUE"""),"Buah Naga") -> Buah Naga | N19: =IFERROR(__xludf.DUMMYFUNCTION("""COMPUTED_VALUE"""),"Salak") -> Salak | O19: =IFERROR(__xludf.DUMMYFUNCTION("""COMPUTED_VALUE"""),"Apel") -> Apel
A20: 46112 | B20: Bumbu Masak Sembako | C20: Tepung Terigu | D20: =IF(C20="","",IFERROR(VLOOKUP(C20,'Master Data'!$B$2:$C$527,2,FALSE),"")) -> Dus | E20: 3 | H20: =IFERROR('Master Data'!E26,"") | I20: =IFERROR(__xludf.DUMMYFUNCTION("IFERROR(TRANSPOSE(FILTER('Master Data'!$B$2:$B$527,'Master Data'!$A$2:$A$527=$B20)),"""")"),"Tepung Terigu") -> Tepung Terigu | J20: =IFERROR(__xludf.DUMMYFUNCTION("""COMPUTED_VALUE"""),"Tepung Tapioka") -> Tepung Tapioka | K20: =IFERROR(__xludf.DUMMYFUNCTION("""COMPUTED_VALUE"""),"Sajiku") -> Sajiku | L20: =IFERROR(__xludf.DUMMYFUNCTION("""COMPUTED_VALUE"""),"Lada") -> Lada | M20: =IFERROR(__xludf.DUMMYFUNCTION("""COMPUTED_VALUE"""),"Minyak Goreng") -> Minyak Goreng | N20: =IFERROR(__xludf.DUMMYFUNCTION("""COMPUTED_VALUE"""),"Maizena") -> Maizena | O20: =IFERROR(__xludf.DUMMYFUNCTION("""COMPUTED_VALUE"""),"Saori") -> Saori | P20: =IFERROR(__xludf.DUMMYFUNCTION("""COMPUTED_VALUE"""),"Tepung Beras") -> Tepung Beras | Q20: =IFERROR(__xludf.DUMMYFUNCTION("""COMPUTED_VALUE"""),"Garam Kasar") -> Garam Kasar | R20: =IFERROR(__xludf.DUMMYFUNCTION("""COMPUTED_VALUE"""),"Garam Halus") -> Garam Halus | S20: =IFERROR(__xludf.DUMMYFUNCTION("""COMPUTED_VALUE"""),"Gula Putih") -> Gula Putih | T20: =IFERROR(__xludf.DUMMYFUNCTION("""COMPUTED_VALUE"""),"Gula Merah") -> Gula Merah | U20: =IFERROR(__xludf.DUMMYFUNCTION("""COMPUTED_VALUE"""),"Kecap") -> Kecap | V20: =IFERROR(__xludf.DUMMYFUNCTION("""COMPUTED_VALUE"""),"Keju") -> Keju | W20: =IFERROR(__xludf.DUMMYFUNCTION("""COMPUTED_VALUE"""),"Bumbu Marinasi") -> Bumbu Marinasi | X20: =IFERROR(__xludf.DUMMYFUNCTION("""COMPUTED_VALUE"""),"Saos Tomat") -> Saos Tomat | Y20: =IFERROR(__xludf.DUMMYFUNCTION("""COMPUTED_VALUE"""),"Tepung Panir") -> Tepung Panir | Z20: =IFERROR(__xludf.DUMMYFUNCTION("""COMPUTED_VALUE"""),"Asem Jawa") -> Asem Jawa
A21: 46112 | B21: Bumbu Masak Sembako | C21: Maizena | D21: =IF(C21="","",IFERROR(VLOOKUP(C21,'Master Data'!$B$2:$C$527,2,FALSE),"")) -> Pack | E21: 7 | H21: =IFERROR('Master Data'!E27,"") | I21: =IFERROR(__xludf.DUMMYFUNCTION("IFERROR(TRANSPOSE(FILTER('Master Data'!$B$2:$B$527,'Master Data'!$A$2:$A$527=$B21)),"""")"),"Tepung Terigu") -> Tepung Terigu | J21: =IFERROR(__xludf.DUMMYFUNCTION("""COMPUTED_VALUE"""),"Tepung Tapioka") -> Tepung Tapioka | K21: =IFERROR(__xludf.DUMMYFUNCTION("""COMPUTED_VALUE"""),"Sajiku") -> Sajiku | L21: =IFERROR(__xludf.DUMMYFUNCTION("""COMPUTED_VALUE"""),"Lada") -> Lada | M21: =IFERROR(__xludf.DUMMYFUNCTION("""COMPUTED_VALUE"""),"Minyak Goreng") -> Minyak Goreng | N21: =IFERROR(__xludf.DUMMYFUNCTION("""COMPUTED_VALUE"""),"Maizena") -> Maizena | O21: =IFERROR(__xludf.DUMMYFUNCTION("""COMPUTED_VALUE"""),"Saori") -> Saori | P21: =IFERROR(__xludf.DUMMYFUNCTION("""COMPUTED_VALUE"""),"Tepung Beras") -> Tepung Beras | Q21: =IFERROR(__xludf.DUMMYFUNCTION("""COMPUTED_VALUE"""),"Garam Kasar") -> Garam Kasar | R21: =IFERROR(__xludf.DUMMYFUNCTION("""COMPUTED_VALUE"""),"Garam Halus") -> Garam Halus | S21: =IFERROR(__xludf.DUMMYFUNCTION("""COMPUTED_VALUE"""),"Gula Putih") -> Gula Putih | T21: =IFERROR(__xludf.DUMMYFUNCTION("""COMPUTED_VALUE"""),"Gula Merah") -> Gula Merah | U21: =IFERROR(__xludf.DUMMYFUNCTION("""COMPUTED_VALUE"""),"Kecap") -> Kecap | V21: =IFERROR(__xludf.DUMMYFUNCTION("""COMPUTED_VALUE"""),"Keju") -> Keju | W21: =IFERROR(__xludf.DUMMYFUNCTION("""COMPUTED_VALUE"""),"Bumbu Marinasi") -> Bumbu Marinasi | X21: =IFERROR(__xludf.DUMMYFUNCTION("""COMPUTED_VALUE"""),"Saos Tomat") -> Saos Tomat | Y21: =IFERROR(__xludf.DUMMYFUNCTION("""COMPUTED_VALUE"""),"Tepung Panir") -> Tepung Panir | Z21: =IFERROR(__xludf.DUMMYFUNCTION("""COMPUTED_VALUE"""),"Asem Jawa") -> Asem Jawa
A22: 46112 | B22: Bumbu Masak Sembako | C22: Saori | D22: =IF(C22="","",IFERROR(VLOOKUP(C22,'Master Data'!$B$2:$C$527,2,FALSE),"")) -> Pcs | E22: 3 | H22: =IFERROR('Master Data'!E28,"") | I22: =IFERROR(__xludf.DUMMYFUNCTION("IFERROR(TRANSPOSE(FILTER('Master Data'!$B$2:$B$527,'Master Data'!$A$2:$A$527=$B22)),"""")"),"Tepung Terigu") -> Tepung Terigu | J22: =IFERROR(__xludf.DUMMYFUNCTION("""COMPUTED_VALUE"""),"Tepung Tapioka") -> Tepung Tapioka | K22: =IFERROR(__xludf.DUMMYFUNCTION("""COMPUTED_VALUE"""),"Sajiku") -> Sajiku | L22: =IFERROR(__xludf.DUMMYFUNCTION("""COMPUTED_VALUE"""),"Lada") -> Lada | M22: =IFERROR(__xludf.DUMMYFUNCTION("""COMPUTED_VALUE"""),"Minyak Goreng") -> Minyak Goreng | N22: =IFERROR(__xludf.DUMMYFUNCTION("""COMPUTED_VALUE"""),"Maizena") -> Maizena | O22: =IFERROR(__xludf.DUMMYFUNCTION("""COMPUTED_VALUE"""),"Saori") -> Saori | P22: =IFERROR(__xludf.DUMMYFUNCTION("""COMPUTED_VALUE"""),"Tepung Beras") -> Tepung Beras | Q22: =IFERROR(__xludf.DUMMYFUNCTION("""COMPUTED_VALUE"""),"Garam Kasar") -> Garam Kasar | R22: =IFERROR(__xludf.DUMMYFUNCTION("""COMPUTED_VALUE"""),"Garam Halus") -> Garam Halus | S22: =IFERROR(__xludf.DUMMYFUNCTION("""COMPUTED_VALUE"""),"Gula Putih") -> Gula Putih | T22: =IFERROR(__xludf.DUMMYFUNCTION("""COMPUTED_VALUE"""),"Gula Merah") -> Gula Merah | U22: =IFERROR(__xludf.DUMMYFUNCTION("""COMPUTED_VALUE"""),"Kecap") -> Kecap | V22: =IFERROR(__xludf.DUMMYFUNCTION("""COMPUTED_VALUE"""),"Keju") -> Keju | W22: =IFERROR(__xludf.DUMMYFUNCTION("""COMPUTED_VALUE"""),"Bumbu Marinasi") -> Bumbu Marinasi | X22: =IFERROR(__xludf.DUMMYFUNCTION("""COMPUTED_VALUE"""),"Saos Tomat") -> Saos Tomat | Y22: =IFERROR(__xludf.DUMMYFUNCTION("""COMPUTED_VALUE"""),"Tepung Panir") -> Tepung Panir | Z22: =IFERROR(__xludf.DUMMYFUNCTION("""COMPUTED_VALUE"""),"Asem Jawa") -> Asem Jawa
A23: 46112 | B23: Bumbu Masak Sembako | C23: Tepung Tapioka | D23: =IF(C23="","",IFERROR(VLOOKUP(C23,'Master Data'!$B$2:$C$527,2,FALSE),"")) -> Dus | E23: 3 | H23: =IFERROR('Master Data'!E29,"") | I23: =IFERROR(__xludf.DUMMYFUNCTION("IFERROR(TRANSPOSE(FILTER('Master Data'!$B$2:$B$527,'Master Data'!$A$2:$A$527=$B23)),"""")"),"Tepung Terigu") -> Tepung Terigu | J23: =IFERROR(__xludf.DUMMYFUNCTION("""COMPUTED_VALUE"""),"Tepung Tapioka") -> Tepung Tapioka | K23: =IFERROR(__xludf.DUMMYFUNCTION("""COMPUTED_VALUE"""),"Sajiku") -> Sajiku | L23: =IFERROR(__xludf.DUMMYFUNCTION("""COMPUTED_VALUE"""),"Lada") -> Lada | M23: =IFERROR(__xludf.DUMMYFUNCTION("""COMPUTED_VALUE"""),"Minyak Goreng") -> Minyak Goreng | N23: =IFERROR(__xludf.DUMMYFUNCTION("""COMPUTED_VALUE"""),"Maizena") -> Maizena | O23: =IFERROR(__xludf.DUMMYFUNCTION("""COMPUTED_VALUE"""),"Saori") -> Saori | P23: =IFERROR(__xludf.DUMMYFUNCTION("""COMPUTED_VALUE"""),"Tepung Beras") -> Tepung Beras | Q23: =IFERROR(__xludf.DUMMYFUNCTION("""COMPUTED_VALUE"""),"Garam Kasar") -> Garam Kasar | R23: =IFERROR(__xludf.DUMMYFUNCTION("""COMPUTED_VALUE"""),"Garam Halus") -> Garam Halus | S23: =IFERROR(__xludf.DUMMYFUNCTION("""COMPUTED_VALUE"""),"Gula Putih") -> Gula Putih | T23: =IFERROR(__xludf.DUMMYFUNCTION("""COMPUTED_VALUE"""),"Gula Merah") -> Gula Merah | U23: =IFERROR(__xludf.DUMMYFUNCTION("""COMPUTED_VALUE"""),"Kecap") -> Kecap | V23: =IFERROR(__xludf.DUMMYFUNCTION("""COMPUTED_VALUE"""),"Keju") -> Keju | W23: =IFERROR(__xludf.DUMMYFUNCTION("""COMPUTED_VALUE"""),"Bumbu Marinasi") -> Bumbu Marinasi | X23: =IFERROR(__xludf.DUMMYFUNCTION("""COMPUTED_VALUE"""),"Saos Tomat") -> Saos Tomat | Y23: =IFERROR(__xludf.DUMMYFUNCTION("""COMPUTED_VALUE"""),"Tepung Panir") -> Tepung Panir | Z23: =IFERROR(__xludf.DUMMYFUNCTION("""COMPUTED_VALUE"""),"Asem Jawa") -> Asem Jawa
A24: 46112 | B24: Bumbu Masak Sembako | C24: Minyak Goreng | D24: =IF(C24="","",IFERROR(VLOOKUP(C24,'Master Data'!$B$2:$C$527,2,FALSE),"")) -> Dus | E24: 1 | H24: =IFERROR('Master Data'!E30,"") | I24: =IFERROR(__xludf.DUMMYFUNCTION("IFERROR(TRANSPOSE(FILTER('Master Data'!$B$2:$B$527,'Master Data'!$A$2:$A$527=$B24)),"""")"),"Tepung Terigu") -> Tepung Terigu | J24: =IFERROR(__xludf.DUMMYFUNCTION("""COMPUTED_VALUE"""),"Tepung Tapioka") -> Tepung Tapioka | K24: =IFERROR(__xludf.DUMMYFUNCTION("""COMPUTED_VALUE"""),"Sajiku") -> Sajiku | L24: =IFERROR(__xludf.DUMMYFUNCTION("""COMPUTED_VALUE"""),"Lada") -> Lada | M24: =IFERROR(__xludf.DUMMYFUNCTION("""COMPUTED_VALUE"""),"Minyak Goreng") -> Minyak Goreng | N24: =IFERROR(__xludf.DUMMYFUNCTION("""COMPUTED_VALUE"""),"Maizena") -> Maizena | O24: =IFERROR(__xludf.DUMMYFUNCTION("""COMPUTED_VALUE"""),"Saori") -> Saori | P24: =IFERROR(__xludf.DUMMYFUNCTION("""COMPUTED_VALUE"""),"Tepung Beras") -> Tepung Beras | Q24: =IFERROR(__xludf.DUMMYFUNCTION("""COMPUTED_VALUE"""),"Garam Kasar") -> Garam Kasar | R24: =IFERROR(__xludf.DUMMYFUNCTION("""COMPUTED_VALUE"""),"Garam Halus") -> Garam Halus | S24: =IFERROR(__xludf.DUMMYFUNCTION("""COMPUTED_VALUE"""),"Gula Putih") -> Gula Putih | T24: =IFERROR(__xludf.DUMMYFUNCTION("""COMPUTED_VALUE"""),"Gula Merah") -> Gula Merah | U24: =IFERROR(__xludf.DUMMYFUNCTION("""COMPUTED_VALUE"""),"Kecap") -> Kecap | V24: =IFERROR(__xludf.DUMMYFUNCTION("""COMPUTED_VALUE"""),"Keju") -> Keju | W24: =IFERROR(__xludf.DUMMYFUNCTION("""COMPUTED_VALUE"""),"Bumbu Marinasi") -> Bumbu Marinasi | X24: =IFERROR(__xludf.DUMMYFUNCTION("""COMPUTED_VALUE"""),"Saos Tomat") -> Saos Tomat | Y24: =IFERROR(__xludf.DUMMYFUNCTION("""COMPUTED_VALUE"""),"Tepung Panir") -> Tepung Panir | Z24: =IFERROR(__xludf.DUMMYFUNCTION("""COMPUTED_VALUE"""),"Asem Jawa") -> Asem Jawa
A25: 46112 | B25: Bumbu Masak Sembako | C25: Garam Kasar | D25: =IF(C25="","",IFERROR(VLOOKUP(C25,'Master Data'!$B$2:$C$527,2,FALSE),"")) -> Pak | E25: 1 | H25: =IFERROR('Master Data'!E31,"") | I25: =IFERROR(__xludf.DUMMYFUNCTION("IFERROR(TRANSPOSE(FILTER('Master Data'!$B$2:$B$527,'Master Data'!$A$2:$A$527=$B25)),"""")"),"Tepung Terigu") -> Tepung Terigu | J25: =IFERROR(__xludf.DUMMYFUNCTION("""COMPUTED_VALUE"""),"Tepung Tapioka") -> Tepung Tapioka | K25: =IFERROR(__xludf.DUMMYFUNCTION("""COMPUTED_VALUE"""),"Sajiku") -> Sajiku | L25: =IFERROR(__xludf.DUMMYFUNCTION("""COMPUTED_VALUE"""),"Lada") -> Lada | M25: =IFERROR(__xludf.DUMMYFUNCTION("""COMPUTED_VALUE"""),"Minyak Goreng") -> Minyak Goreng | N25: =IFERROR(__xludf.DUMMYFUNCTION("""COMPUTED_VALUE"""),"Maizena") -> Maizena | O25: =IFERROR(__xludf.DUMMYFUNCTION("""COMPUTED_VALUE"""),"Saori") -> Saori | P25: =IFERROR(__xludf.DUMMYFUNCTION("""COMPUTED_VALUE"""),"Tepung Beras") -> Tepung Beras | Q25: =IFERROR(__xludf.DUMMYFUNCTION("""COMPUTED_VALUE"""),"Garam Kasar") -> Garam Kasar | R25: =IFERROR(__xludf.DUMMYFUNCTION("""COMPUTED_VALUE"""),"Garam Halus") -> Garam Halus | S25: =IFERROR(__xludf.DUMMYFUNCTION("""COMPUTED_VALUE"""),"Gula Putih") -> Gula Putih | T25: =IFERROR(__xludf.DUMMYFUNCTION("""COMPUTED_VALUE"""),"Gula Merah") -> Gula Merah | U25: =IFERROR(__xludf.DUMMYFUNCTION("""COMPUTED_VALUE"""),"Kecap") -> Kecap | V25: =IFERROR(__xludf.DUMMYFUNCTION("""COMPUTED_VALUE"""),"Keju") -> Keju | W25: =IFERROR(__xludf.DUMMYFUNCTION("""COMPUTED_VALUE"""),"Bumbu Marinasi") -> Bumbu Marinasi | X25: =IFERROR(__xludf.DUMMYFUNCTION("""COMPUTED_VALUE"""),"Saos Tomat") -> Saos Tomat | Y25: =IFERROR(__xludf.DUMMYFUNCTION("""COMPUTED_VALUE"""),"Tepung Panir") -> Tepung Panir | Z25: =IFERROR(__xludf.DUMMYFUNCTION("""COMPUTED_VALUE"""),"Asem Jawa") -> Asem Jawa
A26: 46112 | B26: Bumbu Masak Sembako | C26: Lada | D26: =IF(C26="","",IFERROR(VLOOKUP(C26,'Master Data'!$B$2:$C$527,2,FALSE),"")) -> Pack | E26: 1 | H26: =IFERROR('Master Data'!E33,"") | I26: =IFERROR(__xludf.DUMMYFUNCTION("IFERROR(TRANSPOSE(FILTER('Master Data'!$B$2:$B$527,'Master Data'!$A$2:$A$527=$B26)),"""")"),"Tepung Terigu") -> Tepung Terigu | J26: =IFERROR(__xludf.DUMMYFUNCTION("""COMPUTED_VALUE"""),"Tepung Tapioka") -> Tepung Tapioka | K26: =IFERROR(__xludf.DUMMYFUNCTION("""COMPUTED_VALUE"""),"Sajiku") -> Sajiku | L26: =IFERROR(__xludf.DUMMYFUNCTION("""COMPUTED_VALUE"""),"Lada") -> Lada | M26: =IFERROR(__xludf.DUMMYFUNCTION("""COMPUTED_VALUE"""),"Minyak Goreng") -> Minyak Goreng | N26: =IFERROR(__xludf.DUMMYFUNCTION("""COMPUTED_VALUE"""),"Maizena") -> Maizena | O26: =IFERROR(__xludf.DUMMYFUNCTION("""COMPUTED_VALUE"""),"Saori") -> Saori | P26: =IFERROR(__xludf.DUMMYFUNCTION("""COMPUTED_VALUE"""),"Tepung Beras") -> Tepung Beras | Q26: =IFERROR(__xludf.DUMMYFUNCTION("""COMPUTED_VALUE"""),"Garam Kasar") -> Garam Kasar | R26: =IFERROR(__xludf.DUMMYFUNCTION("""COMPUTED_VALUE"""),"Garam Halus") -> Garam Halus | S26: =IFERROR(__xludf.DUMMYFUNCTION("""COMPUTED_VALUE"""),"Gula Putih") -> Gula Putih | T26: =IFERROR(__xludf.DUMMYFUNCTION("""COMPUTED_VALUE"""),"Gula Merah") -> Gula Merah | U26: =IFERROR(__xludf.DUMMYFUNCTION("""COMPUTED_VALUE"""),"Kecap") -> Kecap | V26: =IFERROR(__xludf.DUMMYFUNCTION("""COMPUTED_VALUE"""),"Keju") -> Keju | W26: =IFERROR(__xludf.DUMMYFUNCTION("""COMPUTED_VALUE"""),"Bumbu Marinasi") -> Bumbu Marinasi | X26: =IFERROR(__xludf.DUMMYFUNCTION("""COMPUTED_VALUE"""),"Saos Tomat") -> Saos Tomat | Y26: =IFERROR(__xludf.DUMMYFUNCTION("""COMPUTED_VALUE"""),"Tepung Panir") -> Tepung Panir | Z26: =IFERROR(__xludf.DUMMYFUNCTION("""COMPUTED_VALUE"""),"Asem Jawa") -> Asem Jawa
A27: 46112 | B27: Bumbu Masak Sembako | C27: Gula | D27: =IF(C27="","",IFERROR(VLOOKUP(C27,'Master Data'!$B$2:$C$527,2,FALSE),"")) | E27: 5 | H27: =IFERROR('Master Data'!E38,"") | I27: =IFERROR(__xludf.DUMMYFUNCTION("IFERROR(TRANSPOSE(FILTER('Master Data'!$B$2:$B$527,'Master Data'!$A$2:$A$527=$B27)),"""")"),"Tepung Terigu") -> Tepung Terigu | J27: =IFERROR(__xludf.DUMMYFUNCTION("""COMPUTED_VALUE"""),"Tepung Tapioka") -> Tepung Tapioka | K27: =IFERROR(__xludf.DUMMYFUNCTION("""COMPUTED_VALUE"""),"Sajiku") -> Sajiku | L27: =IFERROR(__xludf.DUMMYFUNCTION("""COMPUTED_VALUE"""),"Lada") -> Lada | M27: =IFERROR(__xludf.DUMMYFUNCTION("""COMPUTED_VALUE"""),"Minyak Goreng") -> Minyak Goreng | N27: =IFERROR(__xludf.DUMMYFUNCTION("""COMPUTED_VALUE"""),"Maizena") -> Maizena | O27: =IFERROR(__xludf.DUMMYFUNCTION("""COMPUTED_VALUE"""),"Saori") -> Saori | P27: =IFERROR(__xludf.DUMMYFUNCTION("""COMPUTED_VALUE"""),"Tepung Beras") -> Tepung Beras | Q27: =IFERROR(__xludf.DUMMYFUNCTION("""COMPUTED_VALUE"""),"Garam Kasar") -> Garam Kasar | R27: =IFERROR(__xludf.DUMMYFUNCTION("""COMPUTED_VALUE"""),"Garam Halus") -> Garam Halus | S27: =IFERROR(__xludf.DUMMYFUNCTION("""COMPUTED_VALUE"""),"Gula Putih") -> Gula Putih | T27: =IFERROR(__xludf.DUMMYFUNCTION("""COMPUTED_VALUE"""),"Gula Merah") -> Gula Merah | U27: =IFERROR(__xludf.DUMMYFUNCTION("""COMPUTED_VALUE"""),"Kecap") -> Kecap | V27: =IFERROR(__xludf.DUMMYFUNCTION("""COMPUTED_VALUE"""),"Keju") -> Keju | W27: =IFERROR(__xludf.DUMMYFUNCTION("""COMPUTED_VALUE"""),"Bumbu Marinasi") -> Bumbu Marinasi | X27: =IFERROR(__xludf.DUMMYFUNCTION("""COMPUTED_VALUE"""),"Saos Tomat") -> Saos Tomat | Y27: =IFERROR(__xludf.DUMMYFUNCTION("""COMPUTED_VALUE"""),"Tepung Panir") -> Tepung Panir | Z27: =IFERROR(__xludf.DUMMYFUNCTION("""COMPUTED_VALUE"""),"Asem Jawa") -> Asem Jawa
A28: 46112 | B28: Isi Ulang | C28: Galon | D28: =IF(C28="","",IFERROR(VLOOKUP(C28,'Master Data'!$B$2:$C$527,2,FALSE),"")) -> Buah | E28: 28 | H28: =IFERROR('Master Data'!E41,"") | I28: =IFERROR(__xludf.DUMMYFUNCTION("IFERROR(TRANSPOSE(FILTER('Master Data'!$B$2:$B$527,'Master Data'!$A$2:$A$527=$B28)),"""")"),"Galon") -> Galon | J28: =IFERROR(__xludf.DUMMYFUNCTION("""COMPUTED_VALUE"""),"Tedmon") -> Tedmon | K28: =IFERROR(__xludf.DUMMYFUNCTION("""COMPUTED_VALUE"""),"Gas") -> Gas
A29: 46112 | B29: Isi Ulang | C29: Tedmon | D29: =IF(C29="","",IFERROR(VLOOKUP(C29,'Master Data'!$B$2:$C$527,2,FALSE),"")) -> Buah | E29: 8 | H29: =IFERROR('Master Data'!E42,"") | I29: =IFERROR(__xludf.DUMMYFUNCTION("IFERROR(TRANSPOSE(FILTER('Master Data'!$B$2:$B$527,'Master Data'!$A$2:$A$527=$B29)),"""")"),"Galon") -> Galon | J29: =IFERROR(__xludf.DUMMYFUNCTION("""COMPUTED_VALUE"""),"Tedmon") -> Tedmon | K29: =IFERROR(__xludf.DUMMYFUNCTION("""COMPUTED_VALUE"""),"Gas") -> Gas
A30: 46112 | B30: Isi Ulang | C30: Gas | D30: =IF(C30="","",IFERROR(VLOOKUP(C30,'Master Data'!$B$2:$C$527,2,FALSE),"")) -> Tabung | E30: 12 | H30: =IFERROR('Master Data'!E43,"") | I30: =IFERROR(__xludf.DUMMYFUNCTION("IFERROR(TRANSPOSE(FILTER('Master Data'!$B$2:$B$527,'Master Data'!$A$2:$A$527=$B30)),"""")"),"Galon") -> Galon | J30: =IFERROR(__xludf.DUMMYFUNCTION("""COMPUTED_VALUE"""),"Tedmon") -> Tedmon | K30: =IFERROR(__xludf.DUMMYFUNCTION("""COMPUTED_VALUE"""),"Gas") -> Gas
D31: =IF(C31="","",IFERROR(VLOOKUP(C31,'Master Data'!$B$2:$C$527,2,FALSE),"")) | H31: =IFERROR('Master Data'!E44,"") | I31: =IFERROR(__xludf.DUMMYFUNCTION("IFERROR(TRANSPOSE(FILTER('Master Data'!$B$2:$B$527,'Master Data'!$A$2:$A$527=$B31)),"""")"),"")
D32: =IF(C32="","",IFERROR(VLOOKUP(C32,'Master Data'!$B$2:$C$527,2,FALSE),"")) | H32: =IFERROR('Master Data'!E45,"") | I32: =IFERROR(__xludf.DUMMYFUNCTION("IFERROR(TRANSPOSE(FILTER('Master Data'!$B$2:$B$527,'Master Data'!$A$2:$A$527=$B32)),"""")"),"")
D33: =IF(C33="","",IFERROR(VLOOKUP(C33,'Master Data'!$B$2:$C$527,2,FALSE),"")) | H33: =IFERROR('Master Data'!E47,"") | I33: =IFERROR(__xludf.DUMMYFUNCTION("IFERROR(TRANSPOSE(FILTER('Master Data'!$B$2:$B$527,'Master Data'!$A$2:$A$527=$B33)),"""")"),"")
D34: =IF(C34="","",IFERROR(VLOOKUP(C34,'Master Data'!$B$2:$C$527,2,FALSE),"")) | H34: =IFERROR('Master Data'!E48,"") | I34: =IFERROR(__xludf.DUMMYFUNCTION("IFERROR(TRANSPOSE(FILTER('Master Data'!$B$2:$B$527,'Master Data'!$A$2:$A$527=$B34)),"""")"),"")
D35: =IF(C35="","",IFERROR(VLOOKUP(C35,'Master Data'!$B$2:$C$527,2,FALSE),"")) | H35: =IFERROR('Master Data'!E49,"") | I35: =IFERROR(__xludf.DUMMYFUNCTION("IFERROR(TRANSPOSE(FILTER('Master Data'!$B$2:$B$527,'Master Data'!$A$2:$A$527=$B35)),"""")"),"")
D36: =IF(C36="","",IFERROR(VLOOKUP(C36,'Master Data'!$B$2:$C$527,2,FALSE),"")) | H36: =IFERROR('Master Data'!E50,"") | I36: =IFERROR(__xludf.DUMMYFUNCTION("IFERROR(TRANSPOSE(FILTER('Master Data'!$B$2:$B$527,'Master Data'!$A$2:$A$527=$B36)),"""")"),"")
D37: =IF(C37="","",IFERROR(VLOOKUP(C37,'Master Data'!$B$2:$C$527,2,FALSE),"")) | H37: =IFERROR('Master Data'!E51,"") | I37: =IFERROR(__xludf.DUMMYFUNCTION("IFERROR(TRANSPOSE(FILTER('Master Data'!$B$2:$B$527,'Master Data'!$A$2:$A$527=$B37)),"""")"),"")
D38: =IF(C38="","",IFERROR(VLOOKUP(C38,'Master Data'!$B$2:$C$527,2,FALSE),"")) | H38: =IFERROR('Master Data'!E52,"") | I38: =IFERROR(__xludf.DUMMYFUNCTION("IFERROR(TRANSPOSE(FILTER('Master Data'!$B$2:$B$527,'Master Data'!$A$2:$A$527=$B38)),"""")"),"")
D39: =IF(C39="","",IFERROR(VLOOKUP(C39,'Master Data'!$B$2:$C$527,2,FALSE),"")) | H39: =IFERROR('Master Data'!E53,"") | I39: =IFERROR(__xludf.DUMMYFUNCTION("IFERROR(TRANSPOSE(FILTER('Master Data'!$B$2:$B$527,'Master Data'!$A$2:$A$527=$B39)),"""")"),"")
D40: =IF(C40="","",IFERROR(VLOOKUP(C40,'Master Data'!$B$2:$C$527,2,FALSE),"")) | H40: =IFERROR('Master Data'!E55,"") | I40: =IFERROR(__xludf.DUMMYFUNCTION("IFERROR(TRANSPOSE(FILTER('Master Data'!$B$2:$B$527,'Master Data'!$A$2:$A$527=$B40)),"""")"),"")
...

Sheet 1 April 2026
H1: Helper Kategori | I1: Helper Pilihan Bahan
A2: SATUAN PELAYANAN PEMENUHAN GIZI (SPPG) BATTU WINANGUN NOTA PEMESANAN BAHAN MAKANAN | H2: =IFERROR('Master Data'!E2,"") -> Karbohidrat
H3: =IFERROR('Master Data'!E3,"") -> Protein Hewani
H4: =IFERROR('Master Data'!E4,"") -> Protein Nabati
H5: =IFERROR('Master Data'!E5,"") -> Sayur
H6: =IFERROR('Master Data'!E6,"") -> Buah
A7: Tanggal | B7: Kategori Makanan | C7: Bahan Makanan | D7: Satuan | E7: Jumlah | H7: =IFERROR('Master Data'!E7,"") -> Bumbu Masak Sayur
A8: 46113 | B8: Karbohidrat | C8: Beras | D8: =IF(C8="","",IFERROR(VLOOKUP(C8,'Master Data'!$B$2:$C$527,2,FALSE),"")) -> Kg | E8: 240 | H8: =IFERROR('Master Data'!E8,"") -> Bumbu Masak Sembako | I8: =IFERROR(__xludf.DUMMYFUNCTION("IFERROR(TRANSPOSE(FILTER('Master Data'!$B$2:$B$527,'Master Data'!$A$2:$A$527=$B8)),"""")"),"Beras") -> Beras | J8: =IFERROR(__xludf.DUMMYFUNCTION("""COMPUTED_VALUE"""),"Mie") -> Mie | K8: =IFERROR(__xludf.DUMMYFUNCTION("""COMPUTED_VALUE"""),"Kentang") -> Kentang | L8: =IFERROR(__xludf.DUMMYFUNCTION("""COMPUTED_VALUE"""),"Jagung") -> Jagung | M8: =IFERROR(__xludf.DUMMYFUNCTION("""COMPUTED_VALUE"""),"Roti") -> Roti | N8: =IFERROR(__xludf.DUMMYFUNCTION("""COMPUTED_VALUE"""),"Singkong") -> Singkong | O8: =IFERROR(__xludf.DUMMYFUNCTION("""COMPUTED_VALUE"""),"Ubi") -> Ubi | P8: =IFERROR(__xludf.DUMMYFUNCTION("""COMPUTED_VALUE"""),"Makaroni") -> Makaroni
A9: 46113 | B9: Protein Hewani | C9: Daging Ayam Tulang (Potong) | D9: =IF(C9="","",IFERROR(VLOOKUP(C9,'Master Data'!$B$2:$C$527,2,FALSE),"")) -> Kg | E9: 230 | H9: =IFERROR('Master Data'!E9,"") -> Isi Ulang | I9: =IFERROR(__xludf.DUMMYFUNCTION("IFERROR(TRANSPOSE(FILTER('Master Data'!$B$2:$B$527,'Master Data'!$A$2:$A$527=$B9)),"""")"),"Daging Ayam Fillet") -> Daging Ayam Fillet | J9: =IFERROR(__xludf.DUMMYFUNCTION("""COMPUTED_VALUE"""),"Daging Ayam Tulang (Potong)") -> Daging Ayam Tulang (Potong) | K9: =IFERROR(__xludf.DUMMYFUNCTION("""COMPUTED_VALUE"""),"Ikan Patin Fillet") -> Ikan Patin Fillet | L9: =IFERROR(__xludf.DUMMYFUNCTION("""COMPUTED_VALUE"""),"Telur") -> Telur | M9: =IFERROR(__xludf.DUMMYFUNCTION("""COMPUTED_VALUE"""),"Ikan giling") -> Ikan giling | N9: =IFERROR(__xludf.DUMMYFUNCTION("""COMPUTED_VALUE"""),"Ayam Giling") -> Ayam Giling | O9: =IFERROR(__xludf.DUMMYFUNCTION("""COMPUTED_VALUE"""),"Daging Sapi") -> Daging Sapi | P9: =IFERROR(__xludf.DUMMYFUNCTION("""COMPUTED_VALUE"""),"Udang") -> Udang | Q9: =IFERROR(__xludf.DUMMYFUNCTION("""COMPUTED_VALUE"""),"Susu UHT") -> Susu UHT
A10: 46113 | B10: Protein Nabati | C10: Tempe | D10: =IF(C10="","",IFERROR(VLOOKUP(C10,'Master Data'!$B$2:$C$527,2,FALSE),"")) -> Kg | E10: 78 | H10: =IFERROR('Master Data'!E10,"") -> Packaging | I10: =IFERROR(__xludf.DUMMYFUNCTION("IFERROR(TRANSPOSE(FILTER('Master Data'!$B$2:$B$527,'Master Data'!$A$2:$A$527=$B10)),"""")"),"Tempe") -> Tempe | J10: =IFERROR(__xludf.DUMMYFUNCTION("""COMPUTED_VALUE"""),"Tahu") -> Tahu | K10: =IFERROR(__xludf.DUMMYFUNCTION("""COMPUTED_VALUE"""),"Kacang Hijau") -> Kacang Hijau | L10: =IFERROR(__xludf.DUMMYFUNCTION("""COMPUTED_VALUE"""),"Kacang Tanah") -> Kacang Tanah | M10: =IFERROR(__xludf.DUMMYFUNCTION("""COMPUTED_VALUE"""),"Kedelai") -> Kedelai | N10: =IFERROR(__xludf.DUMMYFUNCTION("""COMPUTED_VALUE"""),"Oncom") -> Oncom
A11: 46113 | B11: Sayur | C11: Timun | D11: =IF(C11="","",IFERROR(VLOOKUP(C11,'Master Data'!$B$2:$C$527,2,FALSE),"")) -> Kg | E11: 67 | H11: =IFERROR('Master Data'!E12,"") | I11: =IFERROR(__xludf.DUMMYFUNCTION("IFERROR(TRANSPOSE(FILTER('Master Data'!$B$2:$B$527,'Master Data'!$A$2:$A$527=$B11)),"""")"),"Wortel") -> Wortel | J11: =IFERROR(__xludf.DUMMYFUNCTION("""COMPUTED_VALUE"""),"Kacang Panjang") -> Kacang Panjang | K11: =IFERROR(__xludf.DUMMYFUNCTION("""COMPUTED_VALUE"""),"Tauge") -> Tauge | L11: =IFERROR(__xludf.DUMMYFUNCTION("""COMPUTED_VALUE"""),"Kubis") -> Kubis | M11: =IFERROR(__xludf.DUMMYFUNCTION("""COMPUTED_VALUE"""),"Buncis") -> Buncis | N11: =IFERROR(__xludf.DUMMYFUNCTION("""COMPUTED_VALUE"""),"Kembang Kol") -> Kembang Kol | O11: =IFERROR(__xludf.DUMMYFUNCTION("""COMPUTED_VALUE"""),"Sawi Putih") -> Sawi Putih | P11: =IFERROR(__xludf.DUMMYFUNCTION("""COMPUTED_VALUE"""),"Caisin") -> Caisin | Q11: =IFERROR(__xludf.DUMMYFUNCTION("""COMPUTED_VALUE"""),"Timun") -> Timun | R11: =IFERROR(__xludf.DUMMYFUNCTION("""COMPUTED_VALUE"""),"Daun Bawang") -> Daun Bawang | S11: =IFERROR(__xludf.DUMMYFUNCTION("""COMPUTED_VALUE"""),"Labu Siam") -> Labu Siam | T11: =IFERROR(__xludf.DUMMYFUNCTION("""COMPUTED_VALUE"""),"Tomat") -> Tomat | U11: =IFERROR(__xludf.DUMMYFUNCTION("""COMPUTED_VALUE"""),"Kemangi") -> Kemangi | V11: =IFERROR(__xludf.DUMMYFUNCTION("""COMPUTED_VALUE"""),"Jagung ") -> Jagung
A12: 46113 | B12: Sayur | C12: Wortel | D12: =IF(C12="","",IFERROR(VLOOKUP(C12,'Master Data'!$B$2:$C$527,2,FALSE),"")) -> Kg | E12: 128 | H12: =IFERROR('Master Data'!E14,"") | I12: =IFERROR(__xludf.DUMMYFUNCTION("IFERROR(TRANSPOSE(FILTER('Master Data'!$B$2:$B$527,'Master Data'!$A$2:$A$527=$B12)),"""")"),"Wortel") -> Wortel | J12: =IFERROR(__xludf.DUMMYFUNCTION("""COMPUTED_VALUE"""),"Kacang Panjang") -> Kacang Panjang | K12: =IFERROR(__xludf.DUMMYFUNCTION("""COMPUTED_VALUE"""),"Tauge") -> Tauge | L12: =IFERROR(__xludf.DUMMYFUNCTION("""COMPUTED_VALUE"""),"Kubis") -> Kubis | M12: =IFERROR(__xludf.DUMMYFUNCTION("""COMPUTED_VALUE"""),"Buncis") -> Buncis | N12: =IFERROR(__xludf.DUMMYFUNCTION("""COMPUTED_VALUE"""),"Kembang Kol") -> Kembang Kol | O12: =IFERROR(__xludf.DUMMYFUNCTION("""COMPUTED_VALUE"""),"Sawi Putih") -> Sawi Putih | P12: =IFERROR(__xludf.DUMMYFUNCTION("""COMPUTED_VALUE"""),"Caisin") -> Caisin | Q12: =IFERROR(__xludf.DUMMYFUNCTION("""COMPUTED_VALUE"""),"Timun") -> Timun | R12: =IFERROR(__xludf.DUMMYFUNCTION("""COMPUTED_VALUE"""),"Daun Bawang") -> Daun Bawang | S12: =IFERROR(__xludf.DUMMYFUNCTION("""COMPUTED_VALUE"""),"Labu Siam") -> Labu Siam | T12: =IFERROR(__xludf.DUMMYFUNCTION("""COMPUTED_VALUE"""),"Tomat") -> Tomat | U12: =IFERROR(__xludf.DUMMYFUNCTION("""COMPUTED_VALUE"""),"Kemangi") -> Kemangi | V12: =IFERROR(__xludf.DUMMYFUNCTION("""COMPUTED_VALUE"""),"Jagung ") -> Jagung
A13: 46113 | B13: Bumbu Masak Sayur | C13: Cabe Merah | D13: =IF(C13="","",IFERROR(VLOOKUP(C13,'Master Data'!$B$2:$C$527,2,FALSE),"")) -> Kg | E13: 3 | H13: =IFERROR('Master Data'!E17,"") | I13: =IFERROR(__xludf.DUMMYFUNCTION("IFERROR(TRANSPOSE(FILTER('Master Data'!$B$2:$B$527,'Master Data'!$A$2:$A$527=$B13)),"""")"),"Bawang Merah") -> Bawang Merah | J13: =IFERROR(__xludf.DUMMYFUNCTION("""COMPUTED_VALUE"""),"Bawang Putih") -> Bawang Putih | K13: =IFERROR(__xludf.DUMMYFUNCTION("""COMPUTED_VALUE"""),"Laos") -> Laos | L13: =IFERROR(__xludf.DUMMYFUNCTION("""COMPUTED_VALUE"""),"Serai") -> Serai | M13: =IFERROR(__xludf.DUMMYFUNCTION("""COMPUTED_VALUE"""),"Cabe Merah") -> Cabe Merah | N13: =IFERROR(__xludf.DUMMYFUNCTION("""COMPUTED_VALUE"""),"Bawang Bombay") -> Bawang Bombay | O13: =IFERROR(__xludf.DUMMYFUNCTION("""COMPUTED_VALUE"""),"Ketumbar") -> Ketumbar | P13: =IFERROR(__xludf.DUMMYFUNCTION("""COMPUTED_VALUE"""),"Kencur") -> Kencur | Q13: =IFERROR(__xludf.DUMMYFUNCTION("""COMPUTED_VALUE"""),"Kunyit") -> Kunyit | R13: =IFERROR(__xludf.DUMMYFUNCTION("""COMPUTED_VALUE"""),"Jahe") -> Jahe | S13: =IFERROR(__xludf.DUMMYFUNCTION("""COMPUTED_VALUE"""),"Kelapa Parut") -> Kelapa Parut | T13: =IFERROR(__xludf.DUMMYFUNCTION("""COMPUTED_VALUE"""),"Cabe Ijo") -> Cabe Ijo
A14: 46113 | B14: Protein Nabati | C14: Kacang Tanah | D14: =IF(C14="","",IFERROR(VLOOKUP(C14,'Master Data'!$B$2:$C$527,2,FALSE),"")) -> Kg | E14: 6 | H14: =IFERROR('Master Data'!E18,"") | I14: =IFERROR(__xludf.DUMMYFUNCTION("IFERROR(TRANSPOSE(FILTER('Master Data'!$B$2:$B$527,'Master Data'!$A$2:$A$527=$B14)),"""")"),"Tempe") -> Tempe | J14: =IFERROR(__xludf.DUMMYFUNCTION("""COMPUTED_VALUE"""),"Tahu") -> Tahu | K14: =IFERROR(__xludf.DUMMYFUNCTION("""COMPUTED_VALUE"""),"Kacang Hijau") -> Kacang Hijau | L14: =IFERROR(__xludf.DUMMYFUNCTION("""COMPUTED_VALUE"""),"Kacang Tanah") -> Kacang Tanah | M14: =IFERROR(__xludf.DUMMYFUNCTION("""COMPUTED_VALUE"""),"Kedelai") -> Kedelai | N14: =IFERROR(__xludf.DUMMYFUNCTION("""COMPUTED_VALUE"""),"Oncom") -> Oncom
A15: 46113 | B15: Bumbu Masak Sayur | C15: Bawang Merah | D15: =IF(C15="","",IFERROR(VLOOKUP(C15,'Master Data'!$B$2:$C$527,2,FALSE),"")) -> Kg | E15: 6 | H15: =IFERROR('Master Data'!E19,"") | I15: =IFERROR(__xludf.DUMMYFUNCTION("IFERROR(TRANSPOSE(FILTER('Master Data'!$B$2:$B$527,'Master Data'!$A$2:$A$527=$B15)),"""")"),"Bawang Merah") -> Bawang Merah | J15: =IFERROR(__xludf.DUMMYFUNCTION("""COMPUTED_VALUE"""),"Bawang Putih") -> Bawang Putih | K15: =IFERROR(__xludf.DUMMYFUNCTION("""COMPUTED_VALUE"""),"Laos") -> Laos | L15: =IFERROR(__xludf.DUMMYFUNCTION("""COMPUTED_VALUE"""),"Serai") -> Serai | M15: =IFERROR(__xludf.DUMMYFUNCTION("""COMPUTED_VALUE"""),"Cabe Merah") -> Cabe Merah | N15: =IFERROR(__xludf.DUMMYFUNCTION("""COMPUTED_VALUE"""),"Bawang Bombay") -> Bawang Bombay | O15: =IFERROR(__xludf.DUMMYFUNCTION("""COMPUTED_VALUE"""),"Ketumbar") -> Ketumbar | P15: =IFERROR(__xludf.DUMMYFUNCTION("""COMPUTED_VALUE"""),"Kencur") -> Kencur | Q15: =IFERROR(__xludf.DUMMYFUNCTION("""COMPUTED_VALUE"""),"Kunyit") -> Kunyit | R15: =IFERROR(__xludf.DUMMYFUNCTION("""COMPUTED_VALUE"""),"Jahe") -> Jahe | S15: =IFERROR(__xludf.DUMMYFUNCTION("""COMPUTED_VALUE"""),"Kelapa Parut") -> Kelapa Parut | T15: =IFERROR(__xludf.DUMMYFUNCTION("""COMPUTED_VALUE"""),"Cabe Ijo") -> Cabe Ijo
A16: 46113 | B16: Bumbu Masak Sayur | C16: Bawang Putih | D16: =IF(C16="","",IFERROR(VLOOKUP(C16,'Master Data'!$B$2:$C$527,2,FALSE),"")) -> Kg | E16: 5 | H16: =IFERROR('Master Data'!E21,"") | I16: =IFERROR(__xludf.DUMMYFUNCTION("IFERROR(TRANSPOSE(FILTER('Master Data'!$B$2:$B$527,'Master Data'!$A$2:$A$527=$B16)),"""")"),"Bawang Merah") -> Bawang Merah | J16: =IFERROR(__xludf.DUMMYFUNCTION("""COMPUTED_VALUE"""),"Bawang Putih") -> Bawang Putih | K16: =IFERROR(__xludf.DUMMYFUNCTION("""COMPUTED_VALUE"""),"Laos") -> Laos | L16: =IFERROR(__xludf.DUMMYFUNCTION("""COMPUTED_VALUE"""),"Serai") -> Serai | M16: =IFERROR(__xludf.DUMMYFUNCTION("""COMPUTED_VALUE"""),"Cabe Merah") -> Cabe Merah | N16: =IFERROR(__xludf.DUMMYFUNCTION("""COMPUTED_VALUE"""),"Bawang Bombay") -> Bawang Bombay | O16: =IFERROR(__xludf.DUMMYFUNCTION("""COMPUTED_VALUE"""),"Ketumbar") -> Ketumbar | P16: =IFERROR(__xludf.DUMMYFUNCTION("""COMPUTED_VALUE"""),"Kencur") -> Kencur | Q16: =IFERROR(__xludf.DUMMYFUNCTION("""COMPUTED_VALUE"""),"Kunyit") -> Kunyit | R16: =IFERROR(__xludf.DUMMYFUNCTION("""COMPUTED_VALUE"""),"Jahe") -> Jahe | S16: =IFERROR(__xludf.DUMMYFUNCTION("""COMPUTED_VALUE"""),"Kelapa Parut") -> Kelapa Parut | T16: =IFERROR(__xludf.DUMMYFUNCTION("""COMPUTED_VALUE"""),"Cabe Ijo") -> Cabe Ijo
A17: 46113 | B17: Bumbu Masak Sayur | C17: Laos | D17: =IF(C17="","",IFERROR(VLOOKUP(C17,'Master Data'!$B$2:$C$527,2,FALSE),"")) -> Kg | E17: 4 | H17: =IFERROR('Master Data'!E22,"") | I17: =IFERROR(__xludf.DUMMYFUNCTION("IFERROR(TRANSPOSE(FILTER('Master Data'!$B$2:$B$527,'Master Data'!$A$2:$A$527=$B17)),"""")"),"Bawang Merah") -> Bawang Merah | J17: =IFERROR(__xludf.DUMMYFUNCTION("""COMPUTED_VALUE"""),"Bawang Putih") -> Bawang Putih | K17: =IFERROR(__xludf.DUMMYFUNCTION("""COMPUTED_VALUE"""),"Laos") -> Laos | L17: =IFERROR(__xludf.DUMMYFUNCTION("""COMPUTED_VALUE"""),"Serai") -> Serai | M17: =IFERROR(__xludf.DUMMYFUNCTION("""COMPUTED_VALUE"""),"Cabe Merah") -> Cabe Merah | N17: =IFERROR(__xludf.DUMMYFUNCTION("""COMPUTED_VALUE"""),"Bawang Bombay") -> Bawang Bombay | O17: =IFERROR(__xludf.DUMMYFUNCTION("""COMPUTED_VALUE"""),"Ketumbar") -> Ketumbar | P17: =IFERROR(__xludf.DUMMYFUNCTION("""COMPUTED_VALUE"""),"Kencur") -> Kencur | Q17: =IFERROR(__xludf.DUMMYFUNCTION("""COMPUTED_VALUE"""),"Kunyit") -> Kunyit | R17: =IFERROR(__xludf.DUMMYFUNCTION("""COMPUTED_VALUE"""),"Jahe") -> Jahe | S17: =IFERROR(__xludf.DUMMYFUNCTION("""COMPUTED_VALUE"""),"Kelapa Parut") -> Kelapa Parut | T17: =IFERROR(__xludf.DUMMYFUNCTION("""COMPUTED_VALUE"""),"Cabe Ijo") -> Cabe Ijo
A18: 46113 | B18: Bumbu Masak Sayur | C18: Serai | D18: =IF(C18="","",IFERROR(VLOOKUP(C18,'Master Data'!$B$2:$C$527,2,FALSE),"")) -> Ikat | E18: 10 | H18: =IFERROR('Master Data'!E23,"") | I18: =IFERROR(__xludf.DUMMYFUNCTION("IFERROR(TRANSPOSE(FILTER('Master Data'!$B$2:$B$527,'Master Data'!$A$2:$A$527=$B18)),"""")"),"Bawang Merah") -> Bawang Merah | J18: =IFERROR(__xludf.DUMMYFUNCTION("""COMPUTED_VALUE"""),"Bawang Putih") -> Bawang Putih | K18: =IFERROR(__xludf.DUMMYFUNCTION("""COMPUTED_VALUE"""),"Laos") -> Laos | L18: =IFERROR(__xludf.DUMMYFUNCTION("""COMPUTED_VALUE"""),"Serai") -> Serai | M18: =IFERROR(__xludf.DUMMYFUNCTION("""COMPUTED_VALUE"""),"Cabe Merah") -> Cabe Merah | N18: =IFERROR(__xludf.DUMMYFUNCTION("""COMPUTED_VALUE"""),"Bawang Bombay") -> Bawang Bombay | O18: =IFERROR(__xludf.DUMMYFUNCTION("""COMPUTED_VALUE"""),"Ketumbar") -> Ketumbar | P18: =IFERROR(__xludf.DUMMYFUNCTION("""COMPUTED_VALUE"""),"Kencur") -> Kencur | Q18: =IFERROR(__xludf.DUMMYFUNCTION("""COMPUTED_VALUE"""),"Kunyit") -> Kunyit | R18: =IFERROR(__xludf.DUMMYFUNCTION("""COMPUTED_VALUE"""),"Jahe") -> Jahe | S18: =IFERROR(__xludf.DUMMYFUNCTION("""COMPUTED_VALUE"""),"Kelapa Parut") -> Kelapa Parut | T18: =IFERROR(__xludf.DUMMYFUNCTION("""COMPUTED_VALUE"""),"Cabe Ijo") -> Cabe Ijo
A19: 46113 | B19: Bumbu Masak Sayur | C19: Jahe | D19: =IF(C19="","",IFERROR(VLOOKUP(C19,'Master Data'!$B$2:$C$527,2,FALSE),"")) -> Kg | E19: 3 | H19: =IFERROR('Master Data'!E25,"") | I19: =IFERROR(__xludf.DUMMYFUNCTION("IFERROR(TRANSPOSE(FILTER('Master Data'!$B$2:$B$527,'Master Data'!$A$2:$A$527=$B19)),"""")"),"Bawang Merah") -> Bawang Merah | J19: =IFERROR(__xludf.DUMMYFUNCTION("""COMPUTED_VALUE"""),"Bawang Putih") -> Bawang Putih | K19: =IFERROR(__xludf.DUMMYFUNCTION("""COMPUTED_VALUE"""),"Laos") -> Laos | L19: =IFERROR(__xludf.DUMMYFUNCTION("""COMPUTED_VALUE"""),"Serai") -> Serai | M19: =IFERROR(__xludf.DUMMYFUNCTION("""COMPUTED_VALUE"""),"Cabe Merah") -> Cabe Merah | N19: =IFERROR(__xludf.DUMMYFUNCTION("""COMPUTED_VALUE"""),"Bawang Bombay") -> Bawang Bombay | O19: =IFERROR(__xludf.DUMMYFUNCTION("""COMPUTED_VALUE"""),"Ketumbar") -> Ketumbar | P19: =IFERROR(__xludf.DUMMYFUNCTION("""COMPUTED_VALUE"""),"Kencur") -> Kencur | Q19: =IFERROR(__xludf.DUMMYFUNCTION("""COMPUTED_VALUE"""),"Kunyit") -> Kunyit | R19: =IFERROR(__xludf.DUMMYFUNCTION("""COMPUTED_VALUE"""),"Jahe") -> Jahe | S19: =IFERROR(__xludf.DUMMYFUNCTION("""COMPUTED_VALUE"""),"Kelapa Parut") -> Kelapa Parut | T19: =IFERROR(__xludf.DUMMYFUNCTION("""COMPUTED_VALUE"""),"Cabe Ijo") -> Cabe Ijo
A20: 46113 | B20: Bumbu Masak Sembako | C20: Gula Merah | D20: =IF(C20="","",IFERROR(VLOOKUP(C20,'Master Data'!$B$2:$C$527,2,FALSE),"")) -> Kg | E20: 5 | H20: =IFERROR('Master Data'!E26,"") | I20: =IFERROR(__xludf.DUMMYFUNCTION("IFERROR(TRANSPOSE(FILTER('Master Data'!$B$2:$B$527,'Master Data'!$A$2:$A$527=$B20)),"""")"),"Tepung Terigu") -> Tepung Terigu | J20: =IFERROR(__xludf.DUMMYFUNCTION("""COMPUTED_VALUE"""),"Tepung Tapioka") -> Tepung Tapioka | K20: =IFERROR(__xludf.DUMMYFUNCTION("""COMPUTED_VALUE"""),"Sajiku") -> Sajiku | L20: =IFERROR(__xludf.DUMMYFUNCTION("""COMPUTED_VALUE"""),"Lada") -> Lada | M20: =IFERROR(__xludf.DUMMYFUNCTION("""COMPUTED_VALUE"""),"Minyak Goreng") -> Minyak Goreng | N20: =IFERROR(__xludf.DUMMYFUNCTION("""COMPUTED_VALUE"""),"Maizena") -> Maizena | O20: =IFERROR(__xludf.DUMMYFUNCTION("""COMPUTED_VALUE"""),"Saori") -> Saori | P20: =IFERROR(__xludf.DUMMYFUNCTION("""COMPUTED_VALUE"""),"Tepung Beras") -> Tepung Beras | Q20: =IFERROR(__xludf.DUMMYFUNCTION("""COMPUTED_VALUE"""),"Garam Kasar") -> Garam Kasar | R20: =IFERROR(__xludf.DUMMYFUNCTION("""COMPUTED_VALUE"""),"Garam Halus") -> Garam Halus | S20: =IFERROR(__xludf.DUMMYFUNCTION("""COMPUTED_VALUE"""),"Gula Putih") -> Gula Putih | T20: =IFERROR(__xludf.DUMMYFUNCTION("""COMPUTED_VALUE"""),"Gula Merah") -> Gula Merah | U20: =IFERROR(__xludf.DUMMYFUNCTION("""COMPUTED_VALUE"""),"Kecap") -> Kecap | V20: =IFERROR(__xludf.DUMMYFUNCTION("""COMPUTED_VALUE"""),"Keju") -> Keju | W20: =IFERROR(__xludf.DUMMYFUNCTION("""COMPUTED_VALUE"""),"Bumbu Marinasi") -> Bumbu Marinasi | X20: =IFERROR(__xludf.DUMMYFUNCTION("""COMPUTED_VALUE"""),"Saos Tomat") -> Saos Tomat | Y20: =IFERROR(__xludf.DUMMYFUNCTION("""COMPUTED_VALUE"""),"Tepung Panir") -> Tepung Panir | Z20: =IFERROR(__xludf.DUMMYFUNCTION("""COMPUTED_VALUE"""),"Asem Jawa") -> Asem Jawa
A21: 46113 | B21: Buah | C21: Semangka | D21: =IF(C21="","",IFERROR(VLOOKUP(C21,'Master Data'!$B$2:$C$527,2,FALSE),"")) -> Kg | E21: 669 | H21: =IFERROR('Master Data'!E27,"") | I21: =IFERROR(__xludf.DUMMYFUNCTION("IFERROR(TRANSPOSE(FILTER('Master Data'!$B$2:$B$527,'Master Data'!$A$2:$A$527=$B21)),"""")"),"Melon") -> Melon | J21: =IFERROR(__xludf.DUMMYFUNCTION("""COMPUTED_VALUE"""),"Semangka") -> Semangka | K21: =IFERROR(__xludf.DUMMYFUNCTION("""COMPUTED_VALUE"""),"Jeruk") -> Jeruk | L21: =IFERROR(__xludf.DUMMYFUNCTION("""COMPUTED_VALUE"""),"Pisang") -> Pisang | M21: =IFERROR(__xludf.DUMMYFUNCTION("""COMPUTED_VALUE"""),"Buah Naga") -> Buah Naga | N21: =IFERROR(__xludf.DUMMYFUNCTION("""COMPUTED_VALUE"""),"Salak") -> Salak | O21: =IFERROR(__xludf.DUMMYFUNCTION("""COMPUTED_VALUE"""),"Apel") -> Apel
A22: 46113 | B22: Bumbu Masak Sembako | C22: Minyak Goreng | D22: =IF(C22="","",IFERROR(VLOOKUP(C22,'Master Data'!$B$2:$C$527,2,FALSE),"")) -> Dus | E22: 2 | H22: =IFERROR('Master Data'!E28,"") | I22: =IFERROR(__xludf.DUMMYFUNCTION("IFERROR(TRANSPOSE(FILTER('Master Data'!$B$2:$B$527,'Master Data'!$A$2:$A$527=$B22)),"""")"),"Tepung Terigu") -> Tepung Terigu | J22: =IFERROR(__xludf.DUMMYFUNCTION("""COMPUTED_VALUE"""),"Tepung Tapioka") -> Tepung Tapioka | K22: =IFERROR(__xludf.DUMMYFUNCTION("""COMPUTED_VALUE"""),"Sajiku") -> Sajiku | L22: =IFERROR(__xludf.DUMMYFUNCTION("""COMPUTED_VALUE"""),"Lada") -> Lada | M22: =IFERROR(__xludf.DUMMYFUNCTION("""COMPUTED_VALUE"""),"Minyak Goreng") -> Minyak Goreng | N22: =IFERROR(__xludf.DUMMYFUNCTION("""COMPUTED_VALUE"""),"Maizena") -> Maizena | O22: =IFERROR(__xludf.DUMMYFUNCTION("""COMPUTED_VALUE"""),"Saori") -> Saori | P22: =IFERROR(__xludf.DUMMYFUNCTION("""COMPUTED_VALUE"""),"Tepung Beras") -> Tepung Beras | Q22: =IFERROR(__xludf.DUMMYFUNCTION("""COMPUTED_VALUE"""),"Garam Kasar") -> Garam Kasar | R22: =IFERROR(__xludf.DUMMYFUNCTION("""COMPUTED_VALUE"""),"Garam Halus") -> Garam Halus | S22: =IFERROR(__xludf.DUMMYFUNCTION("""COMPUTED_VALUE"""),"Gula Putih") -> Gula Putih | T22: =IFERROR(__xludf.DUMMYFUNCTION("""COMPUTED_VALUE"""),"Gula Merah") -> Gula Merah | U22: =IFERROR(__xludf.DUMMYFUNCTION("""COMPUTED_VALUE"""),"Kecap") -> Kecap | V22: =IFERROR(__xludf.DUMMYFUNCTION("""COMPUTED_VALUE"""),"Keju") -> Keju | W22: =IFERROR(__xludf.DUMMYFUNCTION("""COMPUTED_VALUE"""),"Bumbu Marinasi") -> Bumbu Marinasi | X22: =IFERROR(__xludf.DUMMYFUNCTION("""COMPUTED_VALUE"""),"Saos Tomat") -> Saos Tomat | Y22: =IFERROR(__xludf.DUMMYFUNCTION("""COMPUTED_VALUE"""),"Tepung Panir") -> Tepung Panir | Z22: =IFERROR(__xludf.DUMMYFUNCTION("""COMPUTED_VALUE"""),"Asem Jawa") -> Asem Jawa
A23: 46113 | B23: Bumbu Masak Sembako | C23: Gula Putih | D23: =IF(C23="","",IFERROR(VLOOKUP(C23,'Master Data'!$B$2:$C$527,2,FALSE),"")) -> Kg | E23: 10 | H23: =IFERROR('Master Data'!E29,"") | I23: =IFERROR(__xludf.DUMMYFUNCTION("IFERROR(TRANSPOSE(FILTER('Master Data'!$B$2:$B$527,'Master Data'!$A$2:$A$527=$B23)),"""")"),"Tepung Terigu") -> Tepung Terigu | J23: =IFERROR(__xludf.DUMMYFUNCTION("""COMPUTED_VALUE"""),"Tepung Tapioka") -> Tepung Tapioka | K23: =IFERROR(__xludf.DUMMYFUNCTION("""COMPUTED_VALUE"""),"Sajiku") -> Sajiku | L23: =IFERROR(__xludf.DUMMYFUNCTION("""COMPUTED_VALUE"""),"Lada") -> Lada | M23: =IFERROR(__xludf.DUMMYFUNCTION("""COMPUTED_VALUE"""),"Minyak Goreng") -> Minyak Goreng | N23: =IFERROR(__xludf.DUMMYFUNCTION("""COMPUTED_VALUE"""),"Maizena") -> Maizena | O23: =IFERROR(__xludf.DUMMYFUNCTION("""COMPUTED_VALUE"""),"Saori") -> Saori | P23: =IFERROR(__xludf.DUMMYFUNCTION("""COMPUTED_VALUE"""),"Tepung Beras") -> Tepung Beras | Q23: =IFERROR(__xludf.DUMMYFUNCTION("""COMPUTED_VALUE"""),"Garam Kasar") -> Garam Kasar | R23: =IFERROR(__xludf.DUMMYFUNCTION("""COMPUTED_VALUE"""),"Garam Halus") -> Garam Halus | S23: =IFERROR(__xludf.DUMMYFUNCTION("""COMPUTED_VALUE"""),"Gula Putih") -> Gula Putih | T23: =IFERROR(__xludf.DUMMYFUNCTION("""COMPUTED_VALUE"""),"Gula Merah") -> Gula Merah | U23: =IFERROR(__xludf.DUMMYFUNCTION("""COMPUTED_VALUE"""),"Kecap") -> Kecap | V23: =IFERROR(__xludf.DUMMYFUNCTION("""COMPUTED_VALUE"""),"Keju") -> Keju | W23: =IFERROR(__xludf.DUMMYFUNCTION("""COMPUTED_VALUE"""),"Bumbu Marinasi") -> Bumbu Marinasi | X23: =IFERROR(__xludf.DUMMYFUNCTION("""COMPUTED_VALUE"""),"Saos Tomat") -> Saos Tomat | Y23: =IFERROR(__xludf.DUMMYFUNCTION("""COMPUTED_VALUE"""),"Tepung Panir") -> Tepung Panir | Z23: =IFERROR(__xludf.DUMMYFUNCTION("""COMPUTED_VALUE"""),"Asem Jawa") -> Asem Jawa
A24: 46113 | B24: Bumbu Masak Sembako | C24: Kecap | D24: =IF(C24="","",IFERROR(VLOOKUP(C24,'Master Data'!$B$2:$C$527,2,FALSE),"")) -> Pcs | E24: 5 | H24: =IFERROR('Master Data'!E30,"") | I24: =IFERROR(__xludf.DUMMYFUNCTION("IFERROR(TRANSPOSE(FILTER('Master Data'!$B$2:$B$527,'Master Data'!$A$2:$A$527=$B24)),"""")"),"Tepung Terigu") -> Tepung Terigu | J24: =IFERROR(__xludf.DUMMYFUNCTION("""COMPUTED_VALUE"""),"Tepung Tapioka") -> Tepung Tapioka | K24: =IFERROR(__xludf.DUMMYFUNCTION("""COMPUTED_VALUE"""),"Sajiku") -> Sajiku | L24: =IFERROR(__xludf.DUMMYFUNCTION("""COMPUTED_VALUE"""),"Lada") -> Lada | M24: =IFERROR(__xludf.DUMMYFUNCTION("""COMPUTED_VALUE"""),"Minyak Goreng") -> Minyak Goreng | N24: =IFERROR(__xludf.DUMMYFUNCTION("""COMPUTED_VALUE"""),"Maizena") -> Maizena | O24: =IFERROR(__xludf.DUMMYFUNCTION("""COMPUTED_VALUE"""),"Saori") -> Saori | P24: =IFERROR(__xludf.DUMMYFUNCTION("""COMPUTED_VALUE"""),"Tepung Beras") -> Tepung Beras | Q24: =IFERROR(__xludf.DUMMYFUNCTION("""COMPUTED_VALUE"""),"Garam Kasar") -> Garam Kasar | R24: =IFERROR(__xludf.DUMMYFUNCTION("""COMPUTED_VALUE"""),"Garam Halus") -> Garam Halus | S24: =IFERROR(__xludf.DUMMYFUNCTION("""COMPUTED_VALUE"""),"Gula Putih") -> Gula Putih | T24: =IFERROR(__xludf.DUMMYFUNCTION("""COMPUTED_VALUE"""),"Gula Merah") -> Gula Merah | U24: =IFERROR(__xludf.DUMMYFUNCTION("""COMPUTED_VALUE"""),"Kecap") -> Kecap | V24: =IFERROR(__xludf.DUMMYFUNCTION("""COMPUTED_VALUE"""),"Keju") -> Keju | W24: =IFERROR(__xludf.DUMMYFUNCTION("""COMPUTED_VALUE"""),"Bumbu Marinasi") -> Bumbu Marinasi | X24: =IFERROR(__xludf.DUMMYFUNCTION("""COMPUTED_VALUE"""),"Saos Tomat") -> Saos Tomat | Y24: =IFERROR(__xludf.DUMMYFUNCTION("""COMPUTED_VALUE"""),"Tepung Panir") -> Tepung Panir | Z24: =IFERROR(__xludf.DUMMYFUNCTION("""COMPUTED_VALUE"""),"Asem Jawa") -> Asem Jawa
A25: 46113 | B25: Bumbu Masak Sembako | C25: Garam Halus | D25: =IF(C25="","",IFERROR(VLOOKUP(C25,'Master Data'!$B$2:$C$527,2,FALSE),"")) -> Pak | E25: 1 | H25: =IFERROR('Master Data'!E31,"") | I25: =IFERROR(__xludf.DUMMYFUNCTION("IFERROR(TRANSPOSE(FILTER('Master Data'!$B$2:$B$527,'Master Data'!$A$2:$A$527=$B25)),"""")"),"Tepung Terigu") -> Tepung Terigu | J25: =IFERROR(__xludf.DUMMYFUNCTION("""COMPUTED_VALUE"""),"Tepung Tapioka") -> Tepung Tapioka | K25: =IFERROR(__xludf.DUMMYFUNCTION("""COMPUTED_VALUE"""),"Sajiku") -> Sajiku | L25: =IFERROR(__xludf.DUMMYFUNCTION("""COMPUTED_VALUE"""),"Lada") -> Lada | M25: =IFERROR(__xludf.DUMMYFUNCTION("""COMPUTED_VALUE"""),"Minyak Goreng") -> Minyak Goreng | N25: =IFERROR(__xludf.DUMMYFUNCTION("""COMPUTED_VALUE"""),"Maizena") -> Maizena | O25: =IFERROR(__xludf.DUMMYFUNCTION("""COMPUTED_VALUE"""),"Saori") -> Saori | P25: =IFERROR(__xludf.DUMMYFUNCTION("""COMPUTED_VALUE"""),"Tepung Beras") -> Tepung Beras | Q25: =IFERROR(__xludf.DUMMYFUNCTION("""COMPUTED_VALUE"""),"Garam Kasar") -> Garam Kasar | R25: =IFERROR(__xludf.DUMMYFUNCTION("""COMPUTED_VALUE"""),"Garam Halus") -> Garam Halus | S25: =IFERROR(__xludf.DUMMYFUNCTION("""COMPUTED_VALUE"""),"Gula Putih") -> Gula Putih | T25: =IFERROR(__xludf.DUMMYFUNCTION("""COMPUTED_VALUE"""),"Gula Merah") -> Gula Merah | U25: =IFERROR(__xludf.DUMMYFUNCTION("""COMPUTED_VALUE"""),"Kecap") -> Kecap | V25: =IFERROR(__xludf.DUMMYFUNCTION("""COMPUTED_VALUE"""),"Keju") -> Keju | W25: =IFERROR(__xludf.DUMMYFUNCTION("""COMPUTED_VALUE"""),"Bumbu Marinasi") -> Bumbu Marinasi | X25: =IFERROR(__xludf.DUMMYFUNCTION("""COMPUTED_VALUE"""),"Saos Tomat") -> Saos Tomat | Y25: =IFERROR(__xludf.DUMMYFUNCTION("""COMPUTED_VALUE"""),"Tepung Panir") -> Tepung Panir | Z25: =IFERROR(__xludf.DUMMYFUNCTION("""COMPUTED_VALUE"""),"Asem Jawa") -> Asem Jawa
A26: 46113 | B26: Bumbu Masak Sembako | C26: Lada | D26: =IF(C26="","",IFERROR(VLOOKUP(C26,'Master Data'!$B$2:$C$527,2,FALSE),"")) -> Pack | E26: 2 | H26: =IFERROR('Master Data'!E33,"") | I26: =IFERROR(__xludf.DUMMYFUNCTION("IFERROR(TRANSPOSE(FILTER('Master Data'!$B$2:$B$527,'Master Data'!$A$2:$A$527=$B26)),"""")"),"Tepung Terigu") -> Tepung Terigu | J26: =IFERROR(__xludf.DUMMYFUNCTION("""COMPUTED_VALUE"""),"Tepung Tapioka") -> Tepung Tapioka | K26: =IFERROR(__xludf.DUMMYFUNCTION("""COMPUTED_VALUE"""),"Sajiku") -> Sajiku | L26: =IFERROR(__xludf.DUMMYFUNCTION("""COMPUTED_VALUE"""),"Lada") -> Lada | M26: =IFERROR(__xludf.DUMMYFUNCTION("""COMPUTED_VALUE"""),"Minyak Goreng") -> Minyak Goreng | N26: =IFERROR(__xludf.DUMMYFUNCTION("""COMPUTED_VALUE"""),"Maizena") -> Maizena | O26: =IFERROR(__xludf.DUMMYFUNCTION("""COMPUTED_VALUE"""),"Saori") -> Saori | P26: =IFERROR(__xludf.DUMMYFUNCTION("""COMPUTED_VALUE"""),"Tepung Beras") -> Tepung Beras | Q26: =IFERROR(__xludf.DUMMYFUNCTION("""COMPUTED_VALUE"""),"Garam Kasar") -> Garam Kasar | R26: =IFERROR(__xludf.DUMMYFUNCTION("""COMPUTED_VALUE"""),"Garam Halus") -> Garam Halus | S26: =IFERROR(__xludf.DUMMYFUNCTION("""COMPUTED_VALUE"""),"Gula Putih") -> Gula Putih | T26: =IFERROR(__xludf.DUMMYFUNCTION("""COMPUTED_VALUE"""),"Gula Merah") -> Gula Merah | U26: =IFERROR(__xludf.DUMMYFUNCTION("""COMPUTED_VALUE"""),"Kecap") -> Kecap | V26: =IFERROR(__xludf.DUMMYFUNCTION("""COMPUTED_VALUE"""),"Keju") -> Keju | W26: =IFERROR(__xludf.DUMMYFUNCTION("""COMPUTED_VALUE"""),"Bumbu Marinasi") -> Bumbu Marinasi | X26: =IFERROR(__xludf.DUMMYFUNCTION("""COMPUTED_VALUE"""),"Saos Tomat") -> Saos Tomat | Y26: =IFERROR(__xludf.DUMMYFUNCTION("""COMPUTED_VALUE"""),"Tepung Panir") -> Tepung Panir | Z26: =IFERROR(__xludf.DUMMYFUNCTION("""COMPUTED_VALUE"""),"Asem Jawa") -> Asem Jawa
